Traceback (most recent call last):
  File "/home/vdsukhov/mambaforge/envs/jb/lib/python3.10/site-packages/jupyter_cache/executors/utils.py", line 58, in single_nb_execution
    executenb(
  File "/home/vdsukhov/mambaforge/envs/jb/lib/python3.10/site-packages/nbclient/client.py", line 1305, in execute
    return NotebookClient(nb=nb, resources=resources, km=km, **kwargs).execute()
  File "/home/vdsukhov/mambaforge/envs/jb/lib/python3.10/site-packages/jupyter_core/utils/__init__.py", line 166, in wrapped
    return loop.run_until_complete(inner)
  File "/home/vdsukhov/mambaforge/envs/jb/lib/python3.10/asyncio/base_events.py", line 649, in run_until_complete
    return future.result()
  File "/home/vdsukhov/mambaforge/envs/jb/lib/python3.10/site-packages/nbclient/client.py", line 705, in async_execute
    await self.async_execute_cell(
  File "/home/vdsukhov/mambaforge/envs/jb/lib/python3.10/site-packages/nbclient/client.py", line 1058, in async_execute_cell
    await self._check_raise_for_error(cell, cell_index, exec_reply)
  File "/home/vdsukhov/mambaforge/envs/jb/lib/python3.10/site-packages/nbclient/client.py", line 914, in _check_raise_for_error
    raise CellExecutionError.from_cell_and_msg(cell, exec_reply_content)
nbclient.exceptions.CellExecutionError: An error occurred while executing the following cell:
------------------
line = "xyz"
int_num = int(line)
float_num = float(line)
print("int_num =", int_num)
print("float_num =", float_num)
------------------


[0;31m---------------------------------------------------------------------------[0m
[0;31mValueError[0m                                Traceback (most recent call last)
Cell [0;32mIn[16], line 2[0m
[1;32m      1[0m line [38;5;241m=[39m [38;5;124m"[39m[38;5;124mxyz[39m[38;5;124m"[39m
[0;32m----> 2[0m int_num [38;5;241m=[39m [38;5;28;43mint[39;49m[43m([49m[43mline[49m[43m)[49m
[1;32m      3[0m float_num [38;5;241m=[39m [38;5;28mfloat[39m(line)
[1;32m      4[0m [38;5;28mprint[39m([38;5;124m"[39m[38;5;124mint_num =[39m[38;5;124m"[39m, int_num)

[0;31mValueError[0m: invalid literal for int() with base 10: 'xyz'

